Workbook

Sheet Read_Me
A1: IFRS 9 VERIFIED MASTER
A2: Generated (UTC) | B2: 2026-10-11T12:47:05+00:00
A3: Baseline | B3: 47 selected bank-years (inputs/IFRS9_Selected_Data_Updated_20261010.csv, unchanged; SHA-256 verified).
A4: This run | B4: 71 new bank-years admitted; 9 blank fields filled; 0 corrections. See Progress.
A5: Units | B5: Monetary amounts NGN million; ratios in percentage points. Blank = not admitted or unavailable, never zero.
A6: Entity rule | B6: Historical Nigerian operating bank only; never holding company, consolidated group, foreign subsidiary or segment.
A7: Formulas | B7: Calculated_Ratios holds live formulas over Panel_Inputs; Formula_Check compares them with the Python recomputation.
A8: Evidence | B8: Evidence_Long: inherited records are labelled inherited_not_rechecked_this_run; only reviewed admissions are verified_reported.
A9: Caution | B9: A report link is not a verified value; a verified value is not a complete bank-year; no regressions are estimated here.
A10: allr | B10: allowance_grossloans_pct = 100 * customer-loan allowance / gross customer loans
A11: average_assets | B11: (matched opening assets + closing assets) / 2; both positive
A12: balance_residual | B12: assets - liabilities - equity (NGN million)
A13: broad_coverage | B13: broad_NPL_coverage_pct = 100 * total customer-loan allowance / NPL amount (not NPL-specific)
... A25: stage3_ratio | B25: 100 * Stage 3 gross / gross loans (not a regulatory NPL ratio)

Sheet Panel_Inputs
A1: Admitted operating-bank inputs. NGN million; percentage points. Blank = not admitted, never zero.
A3: bank | B3: year | C3: tier | D3: regime | E3: pat | F3: assets | G3: liabilities | H3: equity | I3: ocf | J3: opening_assets | K3: gross_loans | L3: loan_allowance | M3: net_loans | N3: total_impairment | O3: npl_amount | P3: regulatory_capital | Q3: rwa | R3: stage3_gross | S3: stage3_allowance | T3: car | U3: car_minimum | V3: liquidity | W3: liquidity_admissible | X3: gcu | Y3: source_url | Z3: version_note | AA3: origin
A4: Access | B4: 2013 | C4: Tier 1 | D4: IAS 39 | E4: 26211.844 | F4: 1704094 | G4: 1458912 | H4: 245182 | N4: -7508.216 | O4: 17924.178 | Y4: https://www.accessbankplc.com/access/media/Financial-Report/Quarterly%20Reports/2014-Financial-Statement-Abridged-Report.pdf?ext=.pdf | Z4: Prior source-selection policy retained; original evidence preserved in accompanying pack. | AA4: Prior selected evidence
A5: Access | B5: 2014 | C5: Tier 1 | D5: IAS 39 | E5: 39941.126 | F5: 1981955.7 | G5: 1707799.9 | H5: 274155.78 | J5: 1704094 | N5: 10609.3 | O5: 19966.521 | Y5: https://www.accessbankplc.com/access/media/Financial-Report/Quarterly%20Reports/2014-Financial-Statement-Abridged-Report.pdf?ext=.pdf | Z5: Prior source-selection policy retained; original evidence preserved in accompanying pack. | AA5: Prior selected evidence
A6: Access | B6: 2015 | C6: Tier 1 | D6: IAS 39 | E6: 58924.745 | F6: 2411944.1 | G6: 2051515.2 | H6: 360428.9 | I6: -181246.61 | J6: 1981955.7 | K6: 1270121.4 | L6: 26906.083 | M6: 1243215.3 | N6: 13287.613 | P6: 340521.19 | Q6: 1887612.1 | T6: 18 | U6: 16 | X6: 0 | Y6: https://doclib.ngxgroup.com/Financial_NewsDocs/12658_ACCESS_BANK_-_2015_AUDITED_ACCTS_FINANCIAL_STATEMENTS_MARCH_2016.pdf | Z6: 2015 annual report, as originally reported | AA6: Admitted this run
A7: Access | B7: 2016 | C7: Tier 1 | D7: IAS 39 | E7: 64026.135 | F7: 3094960.5 | G7: 2673281.9 | H7: 421678.62 | I7: -124135.58 | J7: 2411944.1 | K7: 1624837.9 | L7: 30275.514 | M7: 1594562.3 | N7: 17641.127 | P7: 419807.32 | Q7: 2146850 | T7: 19.55 | U7: 16 | X7: 0 | Y7: https://doclib.ngxgroup.com/Financial_NewsDocs/16624_ACCESS_BANK_-_2016_AUDITED_ACCTS_FINANCIAL_STATEMENTS_MARCH_2017.pdf | Z7: 2016 annual report, as originally reported | AA7: Admitted this run
A8: Access | B8: 2017 | C8: Tier 1 | D8: IAS 39 | E8: 53238.822 | F8: 3499684 | G8: 3030192.9 | H8: 469491.1 | I8: 104360.68 | J8: 3094960.5 | K8: 1827572.1 | L8: 56289.402 | M8: 1771282.7 | N8: 29149.849 | P8: 420096.3 | Q8: 2311370.7 | T8: 18.18 | U8: 16 | X8: 0 | Y8: https://doclib.ngxgroup.com/Financial_NewsDocs/21306_ACCESS_BANK_PLC._FINANCIAL_STATEMENTS_MARCH_2018.pdf | Z8: 2017 annual report, as originally reported | AA8: Admitted this run
A9: Access | B9: 2018 | C9: Tier 1 | D9: IFRS 9 | E9: 73596.295 | F9: 3968114.6 | G9: 3527314.9 | H9: 440799.76 | I9: 366002.39 | M9: 1681761.9 | N9: 10702.144 | Y9: https://doclib.ngxgroup.com/Financial_NewsDocs/29309_ACCESS_BANK_PLC._FINANCIAL_STATEMENTS_MARCH_2020.pdf | Z9: 2019 report comparative (not labelled restated) | AA9: Admitted this run
A10: Access | B10: 2019 | C10: Tier 1 | D10: IFRS 9 | E10: 73569.054 | F10: 6311041.3 | G10: 5768100.2 | H10: 542941.1 | I10: 1094573.3 | J10: 3968114.6 | K10: 2662623.1 | L10: 180999.42 | M10: 2481623.7 | N10: 21055.479 | X10: 0 | Y10: https://doclib.ngxgroup.com/Financial_NewsDocs/29309_ACCESS_BANK_PLC._FINANCIAL_STATEMENTS_MARCH_2020.pdf | Z10: 2019 annual report, as originally reported | AA10: Admitted this run
A11: Access | B11: 2020 | C11: Tier 1 | D11: IFRS 9 | E11: 80039.328 | F11: 7624979.7 | G11: 6971084.1 | H11: 653895.66 | I11: -65407.286 | J11: 6307588.2 | K11: 2937918.3 | L11: 119042.54 | M11: 2818875.7 | N11: 39650.58 | P11: 488756.27 | Q11: 3078989.1 | T11: 15.87 | U11: 16 | X11: 0 | Y11: https://doclib.ngxgroup.com/Financial_NewsDocs/32900_ACCESS_BANK_PLC%20_AUDITED_FINANCIAL_STATEMENT_FOR_2020.pdf | Z11: 2020 annual report, as originally reported | AA11: Admitted this run
A12: Access | B12: 2021 | C12: Tier 1 | D12: IFRS 9 | E12: 111326.49 | F12: 9660760.6 | G12: 8789310.4 | H12: 871450.11 | I12: 500834.81 | J12: 7624979.7 | K12: 3343722.2 | L12: 87649.564 | M12: 3256072.7 | N12: 53800.935 | P12: 835939.16 | Q12: 3993848.7 | T12: 20.93 | X12: 0 | Y12: https://doclib.ngxgroup.com/Financial_NewsDocs/35310_ACCESS_BANK_PLC%20_AUDITED_FINANCIAL_STATEMENT_FOR_2021.pdf | Z12: 2021 annual report, as originally reported | AA12: Admitted this run
A13: Access | B13: 2022 | C13: Tier 1 | D13: IFRS 9 | E13: 166660 | F13: 12535280 | G13: 11466613 | H13: 1068667 | I13: 698528 | J13: 9660761 | K13: 4149413 | L13: 65061 | M13: 4084352 | N13: 118681 | P13: 863711 | Q13: 4839820 | T13: 17.85 | Y13: https://www.accessbankplc.com/access/media/Media-PDF-Attachment/2022-FY-Financial-Statement.pdf?ext=.pdf | Z13: 2022 financial statements, as originally reported | AA13: Admitted this run
A14: Ecobank Nigeria | B14: 2013 | C14: Tier 2 | D14: IAS 39 | E14: 11658 | F14: 1460811 | G14: 1304183 | H14: 156628 | I14: 4606 | J14: 1325315 | K14: 660730 | L14: 34823 | M14: 625907 | N14: 32606 | P14: 165746 | Q14: 953338 | T14: 17 | X14: 0 | Y14: https://www.ecobank.com/upload/publication/20160603050431876MVJZ65QMD2/20140717070804117617CS9N8RVrc92013.pdf | Z14: 2013 annual report, as originally reported | AA14: Admitted this run
A15: Ecobank Nigeria | B15: 2014 | C15: Tier 2 | D15: IAS 39 | E15: 29733 | F15: 1772922 | G15: 1574528 | H15: 198394 | I15: -110701 | J15: 1460811 | K15: 930956 | L15: 38235 | M15: 892721 | N15: 32994 | P15: 239281 | Q15: 1492373 | T15: 16 | X15: 0 | Y15: https://www.ecobank.com/upload/publication/20160603050328266BV9KK3KMGZ/20150424114643650413NqzAyDndnW2014.PDF | Z15: 2014 annual report, as originally reported | AA15: Admitted this run
A16: Ecobank Nigeria | B16: 2015 | C16: Tier 2 | D16: IAS 39 | E16: 11304 | F16: 1794348 | G16: 1566561 | H16: 227787 | I16: 24229 | J16: 1772922 | K16: 885701 | L16: 68353 | M16: 817348 | N16: 55740 | P16: 254109 | Q16: 1357098 | T16: 19 | X16: 0 | Y16: https://www.ecobank.com/upload/publication/20160810051714162FAUN9WFV76/20160810051700933X.pdf | Z16: 2015 annual report, as originally reported | AA16: Admitted this run
A17: Ecobank Nigeria | B17: 2016 | C17: Tier 2 | D17: IAS 39 | E17: 5780 | F17: 1808503 | G17: 1587728 | H17: 220775 | N17: 82783 | Y17: https://www.financialafrik.com/wp-content/uploads/2018/05/FINANCIAL_STATEMENT_EBN_2017-2.pdf | Z17: Prior source-selection policy retained; original evidence preserved in accompanying pack. | AA17: Prior selected evidence
A18: Ecobank Nigeria | B18: 2017 | C18: Tier 2 | D18: IAS 39 | E18: 20204 | F18: 1829761 | G18: 1562432 | H18: 267329 | J18: 1808503 | N18: 59901 | Y18: https://www.financialafrik.com/wp-content/uploads/2018/05/FINANCIAL_STATEMENT_EBN_2017-2.pdf | Z18: Prior source-selection policy retained; original evidence preserved in accompanying pack. | AA18: Prior selected evidence
A19: Ecobank Nigeria | B19: 2018 | C19: Tier 2 | D19: IFRS 9 | E19: 27155 | F19: 1956830 | G19: 1709348 | H19: 247482 | I19: 31236 | J19: 1829761 | K19: 926546 | L19: 84071 | M19: 842475 | N19: 27360 | O19: 126844 | P19: 205312 | Q19: 1433545 | T19: 14.3 | X19: 0 | Y19: https://www.ecobank.com/upload/publication/201908161135521993YH9XK3GUU/201908161135142514.pdf | Z19: 2018 annual report, as originally reported | AA19: Admitted this run
A20: Ecobank Nigeria | B20: 2019 | C20: Tier 2 | D20: IFRS 9 | E20: 1256 | F20: 1991040 | G20: 1726770 | H20: 264270 | I20: 49052 | J20: 1927889 | K20: 913082 | L20: 101476 | M20: 811606 | N20: 2704 | O20: 218515 | P20: 236196 | Q20: 1447830 | T20: 16.31 | X20: 0 | Y20: https://www.ecobank.com/upload/publication/20200901042621276B6RH5TBQ22/20200901042502327T.pdf | Z20: 2019 annual report, as originally reported | AA20: Admitted this run
A21: Ecobank Nigeria | B21: 2020 | C21: Tier 2 | D21: IFRS 9 | E21: 8087 | F21: 2186712 | G21: 1887991 | H21: 298721 | I21: -13271 | J21: 1991040 | K21: 993191 | L21: 111609 | M21: 881582 | N21: 9164 | O21: 197204 | P21: 301364 | Q21: 1405676 | T21: 21.44 | X21: 0 | Y21: https://www.ecobank.com/upload/publication/20210803011222677VJB2VFNZ2Y/20210803011214097V.pdf | Z21: 2020 annual report, as originally reported | AA21: Admitted this run
A22: Ecobank Nigeria | B22: 2021 | C22: Tier 2 | D22: IFRS 9 | E22: 9766 | F22: 2475079 | G22: 2196302 | H22: 278777 | I22: -86740 | J22: 2186711 | K22: 1113022 | L22: 97419 | M22: 1015603 | N22: 7041 | O22: 181954 | P22: 170600 | Q22: 1486056 | T22: 11.48 | X22: 0 | Y22: https://www.ecobank.com/upload/publication/20220707035014829GBVPAXGW87/20220707034953065D.pdf | Z22: 2021 annual report, as originally reported | AA22: Admitted this run
A23: Ecobank Nigeria | B23: 2022 | C23: Tier 2 | D23: IFRS 9 | E23: 10396 | F23: 2917689 | G23: 2623076 | H23: 294613 | I23: -75642 | J23: 2475079 | K23: 1190306 | L23: 62880 | M23: 1127426 | N23: 12377 | O23: 82348 | P23: 232070 | Q23: 1748560 | T23: 13.27 | X23: 0 | Y23: https://www.ecobank.com/upload/publication/20240318051756025XSA3RCX9NN/20240318051750118B.pdf | Z23: 2022 annual report, as originally reported | AA23: Admitted this run
A24: Fidelity | B24: 2013 | C24: Tier 2 | D24: IAS 39 | E24: 7721 | F24: 1081217 | G24: 917762 | H24: 163455 | I24: 15048 | J24: 914360 | K24: 442649 | L24: 16573 | N24: 7630 | T24: 26 | Y24: https://www.fidelitybank.ng/documents/FYE%202013%20Audited%20Financial%20Results.pdf | Z24: Prior source-selection policy retained; original evidence preserved in accompanying pack. | AA24: Prior selected evidence
A25: Fidelity | B25: 2014 | C25: Tier 2 | D25: IAS 39 | E25: 13796 | F25: 1187025 | G25: 1013914 | H25: 173111 | I25: 53565 | J25: 1081217 | K25: 559137 | L25: 17451 | M25: 541686 | N25: 4306 | P25: 198886 | Q25: 821527 | T25: 24.21 | U25: 15 | X25: 0 | Y25: https://www.annualreports.com/HostedData/AnnualReportArchive/f/fidelity-bank-plc_2014.pdf | Z25: 2014 annual report, as originally reported | AA25: Admitted this run
A26: Fidelity | B26: 2015 | C26: Tier 2 | D26: IAS 39 | E26: 13904 | F26: 1231722 | G26: 1048206 | H26: 183516 | I26: 107132 | J26: 1187025 | K26: 598978 | L26: 20776 | M26: 578203 | N26: 5764 | P26: 191595 | Q26: 1012062 | T26: 19 | U26: 15 | X26: 0 | Y26: https://www.annualreports.com/HostedData/AnnualReportArchive/f/fidelity-bank-plc_2015.pdf | Z26: 2015 annual report, as originally reported | AA26: Admitted this run
A27: Fidelity | B27: 2016 | C27: Tier 2 | D27: IAS 39 | E27: 9734 | F27: 1298141 | G27: 1112739 | H27: 185402 | I27: -56907 | J27: 1231722 | K27: 743120 | L27: 24719 | M27: 718401 | N27: 8671 | P27: 196913 | Q27: 1138258 | T27: 17.22 | U27: 15 | X27: 0 | Y27: https://www.annualreports.com/HostedData/AnnualReportArchive/f/fidelity-bank-plc_2016.pdf | Z27: 2016 annual report, as originally reported | AA27: Admitted this run
A28: Fidelity | B28: 2017 | C28: Tier 2 | D28: IAS 39 | E28: 18857 | F28: 1379214 | G28: 1175899 | H28: 203315 | I28: -38026 | J28: 1298141 | K28: 795315 | L28: 26578 | M28: 768737 | N28: 11315 | P28: 179341 | Q28: 1118786 | T28: 16.03 | U28: 15 | X28: 0 | Y28: https://www.annualreports.com/HostedData/AnnualReportArchive/f/fidelity-bank-plc_2017.pdf | Z28: 2017 annual report, as originally reported | AA28: Admitted this run
A29: Fidelity | B29: 2018 | C29: Tier 2 | D29: IFRS 9 | E29: 22926 | F29: 1719883 | G29: 1525467 | H29: 194416 | N29: 4215 | Y29: https://www.fidelitybank.ng/documents/2019%20Annual%20report%20Final%20Web%20Version.pdf | Z29: Prior source-selection policy retained; original evidence preserved in accompanying pack. | AA29: Prior selected evidence
A30: Fidelity | B30: 2019 | C30: Tier 2 | D30: IFRS 9 | E30: 28425 | F30: 2114037 | G30: 1880007 | H30: 234030 | J30: 1719883 | N30: -5292 | X30: 0 | Y30: https://www.fidelitybank.ng/documents/2019%20Annual%20report%20Final%20Web%20Version.pdf | Z30: Prior source-selection policy retained; original evidence preserved in accompanying pack. | AA30: Prior selected evidence
A31: Fidelity | B31: 2020 | C31: Tier 2 | D31: IFRS 9 | E31: 26650 | F31: 2758148 | G31: 2484615 | H31: 273533 | I31: 242619 | J31: 2114037 | K31: 1393624 | L31: 67518 | M31: 1326106 | N31: 16858 | P31: 243690 | Q31: 1340211 | T31: 18.18 | U31: 15 | X31: 0 | Y31: https://www.annualreports.com/HostedData/AnnualReportArchive/f/fidelity-bank-plc_2020.pdf | Z31: 2020 annual report, as originally reported | AA31: Admitted this run
A32: Fidelity | B32: 2021 | C32: Tier 2 | D32: IFRS 9 | E32: 23104 | F32: 3280454 | G32: 2995160 | H32: 285294 | I32: -107190 | K32: 1732543 | L32: 74131 | M32: 1658412 | N32: 7034 | P32: 292323 | Q32: 1526722 | T32: 19.15 | U32: 15 | Y32: https://www.fidelitybank.ng/documents/Fidelity-Bank-Plc-2022-Annual-Report.pdf | Z32: 2022 annual report; 2021 restated comparative | AA32: Admitted this run
A33: Fidelity | B33: 2022 | C33: Tier 2 | D33: IFRS 9 | E33: 46724 | F33: 3989009 | G33: 3674649 | H33: 314360 | I33: 297592 | J33: 3280454 | K33: 2196760 | L33: 80548 | M33: 2116212 | N33: 5443 | P33: 289500 | Q33: 1595729 | T33: 18.14 | U33: 15 | X33: 0 | Y33: https://www.fidelitybank.ng/documents/Fidelity-Bank-Plc-2022-Annual-Report.pdf | Z33: 2022 annual report, as originally reported | AA33: Admitted this run
A34: First Bank | B34: 2013 | C34: Tier 1 | D34: IAS 39 | E34: 59365 | F34: 3246579 | G34: 2895870 | H34: 350709 | I34: 179950 | K34: 1515288 | L34: 41449 | N34: 19838 | T34: 13.54 | Y34: https://first-holdco.com/wp-content/uploads/2021/02/First_Bank_of_Nigeria_Ltd_2014_Annual_Report.pdf | Z34: Prior source-selection policy retained; original evidence preserved in accompanying pack. | AA34: Prior selected evidence
A35: First Bank | B35: 2014 | C35: Tier 1 | D35: IAS 39 | E35: 79351 | F35: 3490871 | G35: 3067824 | H35: 423047 | I35: -506665 | J35: 3246579 | K35: 1832107 | L35: 38070 | N35: 20924 | T35: 15.78 | Y35: https://first-holdco.com/wp-content/uploads/2021/02/First_Bank_of_Nigeria_Ltd_2014_Annual_Report.pdf | Z35: Prior source-selection policy retained; original evidence preserved in accompanying pack. | AA35: Prior selected evidence
A36: First Bank | B36: 2015 | C36: Tier 1 | D36: IAS 39 | E36: 37 | F36: 3332375 | G36: 2872628 | H36: 459747 | I36: 305952 | J36: 3490871 | K36: 1594936 | L36: 137651 | M36: 1457285 | N36: 120046 | P36: 430099 | Q36: 2518285 | T36: 17.08 | U36: 15 | Y36: https://first-holdco.com/wp-content/uploads/2021/02/First_Bank_of_Nigeria_Ltd_2015_Annual_Report.pdf | Z36: 2015 annual report, as originally reported | AA36: Admitted this run
A37: First Bank | B37: 2016 | C37: Tier 1 | D37: IAS 39 | E37: 50072 | F37: 3557782 | G37: 3071695 | H37: 486087 | I37: -171230 | K37: 1933407 | L37: 240695 | M37: 1692712 | P37: 501256 | Q37: 2818158 | T37: 17.79 | U37: 15 | X37: 0 | Y37: https://first-holdco.com/wp-content/uploads/2021/02/First-Bank-of-Nigeria-Ltd-FY-2017-Financial-Statements.pdf | Z37: FY2017 financial statements; 2016 comparative, not labelled restated | AA37: Admitted this run
A38: First Bank | B38: 2017 | C38: Tier 1 | D38: IAS 39 | E38: 46918 | F38: 3777039 | G38: 3197196 | H38: 579843 | I38: 113212 | J38: 3557782 | K38: 1837515 | L38: 178719 | M38: 1658796 | P38: 535692 | Q38: 3019880 | T38: 17.74 | U38: 15 | Y38: https://first-holdco.com/wp-content/uploads/2021/02/First-Bank-of-Nigeria-Ltd-FY-2017-Financial-Statements.pdf | Z38: FY2017 financial statements, as originally reported | AA38: Admitted this run
A39: First Bank | B39: 2018 | C39: Tier 1 | D39: IFRS 9 | E39: 56952 | F39: 3985907 | G39: 3543223 | H39: 442684 | I39: 327497 | J39: 3777039 | K39: 1728964 | L39: 277549 | M39: 1451415 | N39: 61865 | P39: 269341 | Q39: 2527208 | T39: 10.66 | X39: 0 | Y39: https://ise-prodnr-eu-west-1-data-integration.s3-eu-west-1.amazonaws.com/legacy/Prospectus+-+Standalone_bccce739-ac65-4a0d-82bc-7ef4406d2573.PDF | Z39: FY2018 financial statements, as originally reported (reproduced in FBN Finance prospectus) | AA39: Admitted this run
A40: First Bank | B40: 2019 | C40: Tier 1 | D40: IFRS 9 | E40: 43917 | F40: 4668279 | G40: 4128814 | H40: 539465 | I40: -218752 | J40: 3985907 | K40: 1618817 | L40: 59314 | M40: 1559504 | N40: 46640 | P40: 332265 | Q40: 2978121 | T40: 11.16 | X40: 0 | Y40: https://ise-prodnr-eu-west-1-data-integration.s3-eu-west-1.amazonaws.com/legacy/Prospectus+-+Standalone_bccce739-ac65-4a0d-82bc-7ef4406d2573.PDF | Z40: FY2019 financial statements, as originally reported (reproduced in FBN Finance prospectus) | AA40: Admitted this run
A41: First Bank | B41: 2022 | C41: Tier 1 | D41: IFRS 9 | E41: 91415 | F41: 8125060 | G41: 7372174 | H41: 752886 | M41: 3301779 | N41: 49773 | Y41: https://cdn.businessday.ng/wp-content/uploads/2024/05/BD_20240529.pdf | Z41: FY2023 audited summary financial statements, 2022 comparative (later-year presentation; not the 2022 annual report) | AA41: Admitted this run
...

Sheet Calculated_Ratios
A1: Formulas reference Panel_Inputs. Python-recomputed values are compared in Formula_Check.
A3: bank | B3: year | C3: average_assets | D3: roa | E3: eqta | F3: ocf_ratio | G3: allr | H3: car_computed | I3: impairment_assets | J3: broad_coverage | K3: npl_calc | L3: stage3_ratio | M3: stage3_coverage | N3: roa_closing | O3: leverage | P3: ln_assets | Q3: balance_residual | R3: loan_residual | S3: liquidity_used | T3: car_buffer
A4: =Panel_Inputs!A4 -> Access | B4: =Panel_Inputs!B4 -> 2013 | C4: =IF(AND(ISNUMBER(Panel_Inputs!F4),ISNUMBER(Panel_Inputs!J4)),IF(AND(Panel_Inputs!F4>0,Panel_Inputs!J4>0),(Panel_Inputs!F4+Panel_Inputs!J4)/2,""),"") | D4: =IF(AND(ISNUMBER(Panel_Inputs!E4),ISNUMBER(C4)),IF(C4>0,100*Panel_Inputs!E4/C4,""),"") | E4: =IF(AND(ISNUMBER(Panel_Inputs!H4),ISNUMBER(Panel_Inputs!F4)),IF(Panel_Inputs!F4>0,100*Panel_Inputs!H4/Panel_Inputs!F4,""),"") -> 14.387821 | F4: =IF(AND(ISNUMBER(Panel_Inputs!I4),ISNUMBER(C4)),IF(C4>0,100*Panel_Inputs!I4/C4,""),"") | G4: =IF(AND(ISNUMBER(Panel_Inputs!L4),ISNUMBER(Panel_Inputs!K4)),IF(Panel_Inputs!K4>0,100*Panel_Inputs!L4/Panel_Inputs!K4,""),"") | H4: =IF(AND(ISNUMBER(Panel_Inputs!P4),ISNUMBER(Panel_Inputs!Q4)),IF(Panel_Inputs!Q4>0,100*Panel_Inputs!P4/Panel_Inputs!Q4,""),"") | I4: =IF(AND(ISNUMBER(Panel_Inputs!N4),ISNUMBER(C4)),IF(C4>0,100*Panel_Inputs!N4/C4,""),"") | J4: =IF(AND(ISNUMBER(Panel_Inputs!L4),ISNUMBER(Panel_Inputs!O4)),IF(Panel_Inputs!O4>0,100*Panel_Inputs!L4/Panel_Inputs!O4,""),"") | K4: =IF(AND(ISNUMBER(Panel_Inputs!O4),ISNUMBER(Panel_Inputs!K4)),IF(Panel_Inputs!K4>0,100*Panel_Inputs!O4/Panel_Inputs!K4,""),"") | L4: =IF(AND(ISNUMBER(Panel_Inputs!R4),ISNUMBER(Panel_Inputs!K4)),IF(Panel_Inputs!K4>0,100*Panel_Inputs!R4/Panel_Inputs!K4,""),"") | M4: =IF(AND(ISNUMBER(Panel_Inputs!S4),ISNUMBER(Panel_Inputs!R4)),IF(Panel_Inputs!R4>0,100*Panel_Inputs!S4/Panel_Inputs!R4,""),"") | N4: =IF(AND(ISNUMBER(Panel_Inputs!E4),ISNUMBER(Panel_Inputs!F4)),IF(Panel_Inputs!F4>0,100*Panel_Inputs!E4/Panel_Inputs!F4,""),"") -> 1.5381689 | O4: =IF(AND(ISNUMBER(Panel_Inputs!G4),ISNUMBER(Panel_Inputs!F4)),IF(Panel_Inputs!F4>0,100*Panel_Inputs!G4/Panel_Inputs!F4,""),"") -> 85.612179 | P4: =IF(ISNUMBER(Panel_Inputs!F4),IF(Panel_Inputs!F4>0,LN(Panel_Inputs!F4),""),"") -> 14.348544 | Q4: =IF(AND(ISNUMBER(Panel_Inputs!F4),ISNUMBER(Panel_Inputs!G4),ISNUMBER(Panel_Inputs!H4)),Panel_Inputs!F4-Panel_Inputs!G4-Panel_Inputs!H4,"") -> 0 | R4: =IF(AND(ISNUMBER(Panel_Inputs!K4),ISNUMBER(Panel_Inputs!L4),ISNUMBER(Panel_Inputs!M4)),Panel_Inputs!K4-Panel_Inputs!L4-Panel_Inputs!M4,"") | S4: =IF(AND(ISNUMBER(Panel_Inputs!V4),Panel_Inputs!W4=1),Panel_Inputs!V4,"") | T4: =IF(AND(ISNUMBER(Panel_Inputs!T4),ISNUMBER(Panel_Inputs!U4)),Panel_Inputs!T4-Panel_Inputs!U4,"")
A5: =Panel_Inputs!A5 -> Access | B5: =Panel_Inputs!B5 -> 2014 | C5: =IF(AND(ISNUMBER(Panel_Inputs!F5),ISNUMBER(Panel_Inputs!J5)),IF(AND(Panel_Inputs!F5>0,Panel_Inputs!J5>0),(Panel_Inputs!F5+Panel_Inputs!J5)/2,""),"") -> 1843024.9 | D5: =IF(AND(ISNUMBER(Panel_Inputs!E5),ISNUMBER(C5)),IF(C5>0,100*Panel_Inputs!E5/C5,""),"") -> 2.1671507 | E5: =IF(AND(ISNUMBER(Panel_Inputs!H5),ISNUMBER(Panel_Inputs!F5)),IF(Panel_Inputs!F5>0,100*Panel_Inputs!H5/Panel_Inputs!F5,""),"") -> 13.832589 | F5: =IF(AND(ISNUMBER(Panel_Inputs!I5),ISNUMBER(C5)),IF(C5>0,100*Panel_Inputs!I5/C5,""),"") | G5: =IF(AND(ISNUMBER(Panel_Inputs!L5),ISNUMBER(Panel_Inputs!K5)),IF(Panel_Inputs!K5>0,100*Panel_Inputs!L5/Panel_Inputs!K5,""),"") | H5: =IF(AND(ISNUMBER(Panel_Inputs!P5),ISNUMBER(Panel_Inputs!Q5)),IF(Panel_Inputs!Q5>0,100*Panel_Inputs!P5/Panel_Inputs!Q5,""),"") | I5: =IF(AND(ISNUMBER(Panel_Inputs!N5),ISNUMBER(C5)),IF(C5>0,100*Panel_Inputs!N5/C5,""),"") -> 0.57564606 | J5: =IF(AND(ISNUMBER(Panel_Inputs!L5),ISNUMBER(Panel_Inputs!O5)),IF(Panel_Inputs!O5>0,100*Panel_Inputs!L5/Panel_Inputs!O5,""),"") | K5: =IF(AND(ISNUMBER(Panel_Inputs!O5),ISNUMBER(Panel_Inputs!K5)),IF(Panel_Inputs!K5>0,100*Panel_Inputs!O5/Panel_Inputs!K5,""),"") | L5: =IF(AND(ISNUMBER(Panel_Inputs!R5),ISNUMBER(Panel_Inputs!K5)),IF(Panel_Inputs!K5>0,100*Panel_Inputs!R5/Panel_Inputs!K5,""),"") | M5: =IF(AND(ISNUMBER(Panel_Inputs!S5),ISNUMBER(Panel_Inputs!R5)),IF(Panel_Inputs!R5>0,100*Panel_Inputs!S5/Panel_Inputs!R5,""),"") | N5: =IF(AND(ISNUMBER(Panel_Inputs!E5),ISNUMBER(Panel_Inputs!F5)),IF(Panel_Inputs!F5>0,100*Panel_Inputs!E5/Panel_Inputs!F5,""),"") -> 2.015238 | O5: =IF(AND(ISNUMBER(Panel_Inputs!G5),ISNUMBER(Panel_Inputs!F5)),IF(Panel_Inputs!F5>0,100*Panel_Inputs!G5/Panel_Inputs!F5,""),"") -> 86.167411 | P5: =IF(ISNUMBER(Panel_Inputs!F5),IF(Panel_Inputs!F5>0,LN(Panel_Inputs!F5),""),"") -> 14.499595 | Q5: =IF(AND(ISNUMBER(Panel_Inputs!F5),ISNUMBER(Panel_Inputs!G5),ISNUMBER(Panel_Inputs!H5)),Panel_Inputs!F5-Panel_Inputs!G5-Panel_Inputs!H5,"") -> 0.0010000001 | R5: =IF(AND(ISNUMBER(Panel_Inputs!K5),ISNUMBER(Panel_Inputs!L5),ISNUMBER(Panel_Inputs!M5)),Panel_Inputs!K5-Panel_Inputs!L5-Panel_Inputs!M5,"") | S5: =IF(AND(ISNUMBER(Panel_Inputs!V5),Panel_Inputs!W5=1),Panel_Inputs!V5,"") | T5: =IF(AND(ISNUMBER(Panel_Inputs!T5),ISNUMBER(Panel_Inputs!U5)),Panel_Inputs!T5-Panel_Inputs!U5,"")
A6: =Panel_Inputs!A6 -> Access | B6: =Panel_Inputs!B6 -> 2015 | C6: =IF(AND(ISNUMBER(Panel_Inputs!F6),ISNUMBER(Panel_Inputs!J6)),IF(AND(Panel_Inputs!F6>0,Panel_Inputs!J6>0),(Panel_Inputs!F6+Panel_Inputs!J6)/2,""),"") -> 2196949.9 | D6: =IF(AND(ISNUMBER(Panel_Inputs!E6),ISNUMBER(C6)),IF(C6>0,100*Panel_Inputs!E6/C6,""),"") -> 2.682116 | E6: =IF(AND(ISNUMBER(Panel_Inputs!H6),ISNUMBER(Panel_Inputs!F6)),IF(Panel_Inputs!F6>0,100*Panel_Inputs!H6/Panel_Inputs!F6,""),"") -> 14.943502 | F6: =IF(AND(ISNUMBER(Panel_Inputs!I6),ISNUMBER(C6)),IF(C6>0,100*Panel_Inputs!I6/C6,""),"") -> -8.2499202 | G6: =IF(AND(ISNUMBER(Panel_Inputs!L6),ISNUMBER(Panel_Inputs!K6)),IF(Panel_Inputs!K6>0,100*Panel_Inputs!L6/Panel_Inputs!K6,""),"") -> 2.1183867 | H6: =IF(AND(ISNUMBER(Panel_Inputs!P6),ISNUMBER(Panel_Inputs!Q6)),IF(Panel_Inputs!Q6>0,100*Panel_Inputs!P6/Panel_Inputs!Q6,""),"") -> 18.039786 | I6: =IF(AND(ISNUMBER(Panel_Inputs!N6),ISNUMBER(C6)),IF(C6>0,100*Panel_Inputs!N6/C6,""),"") -> 0.60482094 | J6: =IF(AND(ISNUMBER(Panel_Inputs!L6),ISNUMBER(Panel_Inputs!O6)),IF(Panel_Inputs!O6>0,100*Panel_Inputs!L6/Panel_Inputs!O6,""),"") | K6: =IF(AND(ISNUMBER(Panel_Inputs!O6),ISNUMBER(Panel_Inputs!K6)),IF(Panel_Inputs!K6>0,100*Panel_Inputs!O6/Panel_Inputs!K6,""),"") | L6: =IF(AND(ISNUMBER(Panel_Inputs!R6),ISNUMBER(Panel_Inputs!K6)),IF(Panel_Inputs!K6>0,100*Panel_Inputs!R6/Panel_Inputs!K6,""),"") | M6: =IF(AND(ISNUMBER(Panel_Inputs!S6),ISNUMBER(Panel_Inputs!R6)),IF(Panel_Inputs!R6>0,100*Panel_Inputs!S6/Panel_Inputs!R6,""),"") | N6: =IF(AND(ISNUMBER(Panel_Inputs!E6),ISNUMBER(Panel_Inputs!F6)),IF(Panel_Inputs!F6>0,100*Panel_Inputs!E6/Panel_Inputs!F6,""),"") -> 2.4430395 | O6: =IF(AND(ISNUMBER(Panel_Inputs!G6),ISNUMBER(Panel_Inputs!F6)),IF(Panel_Inputs!F6>0,100*Panel_Inputs!G6/Panel_Inputs!F6,""),"") -> 85.056498 | P6: =IF(ISNUMBER(Panel_Inputs!F6),IF(Panel_Inputs!F6>0,LN(Panel_Inputs!F6),""),"") -> 14.695944 | Q6: =IF(AND(ISNUMBER(Panel_Inputs!F6),ISNUMBER(Panel_Inputs!G6),ISNUMBER(Panel_Inputs!H6)),Panel_Inputs!F6-Panel_Inputs!G6-Panel_Inputs!H6,"") -> 0 | R6: =IF(AND(ISNUMBER(Panel_Inputs!K6),ISNUMBER(Panel_Inputs!L6),ISNUMBER(Panel_Inputs!M6)),Panel_Inputs!K6-Panel_Inputs!L6-Panel_Inputs!M6,"") -> 0 | S6: =IF(AND(ISNUMBER(Panel_Inputs!V6),Panel_Inputs!W6=1),Panel_Inputs!V6,"") | T6: =IF(AND(ISNUMBER(Panel_Inputs!T6),ISNUMBER(Panel_Inputs!U6)),Panel_Inputs!T6-Panel_Inputs!U6,"") -> 2
A7: =Panel_Inputs!A7 -> Access | B7: =Panel_Inputs!B7 -> 2016 | C7: =IF(AND(ISNUMBER(Panel_Inputs!F7),ISNUMBER(Panel_Inputs!J7)),IF(AND(Panel_Inputs!F7>0,Panel_Inputs!J7>0),(Panel_Inputs!F7+Panel_Inputs!J7)/2,""),"") -> 2753452.3 | D7: =IF(AND(ISNUMBER(Panel_Inputs!E7),ISNUMBER(C7)),IF(C7>0,100*Panel_Inputs!E7/C7,""),"") -> 2.325304 | E7: =IF(AND(ISNUMBER(Panel_Inputs!H7),ISNUMBER(Panel_Inputs!F7)),IF(Panel_Inputs!F7>0,100*Panel_Inputs!H7/Panel_Inputs!F7,""),"") -> 13.624685 | F7: =IF(AND(ISNUMBER(Panel_Inputs!I7),ISNUMBER(C7)),IF(C7>0,100*Panel_Inputs!I7/C7,""),"") -> -4.5083614 | G7: =IF(AND(ISNUMBER(Panel_Inputs!L7),ISNUMBER(Panel_Inputs!K7)),IF(Panel_Inputs!K7>0,100*Panel_Inputs!L7/Panel_Inputs!K7,""),"") -> 1.8632945 | H7: =IF(AND(ISNUMBER(Panel_Inputs!P7),ISNUMBER(Panel_Inputs!Q7)),IF(Panel_Inputs!Q7>0,100*Panel_Inputs!P7/Panel_Inputs!Q7,""),"") -> 19.554571 | I7: =IF(AND(ISNUMBER(Panel_Inputs!N7),ISNUMBER(C7)),IF(C7>0,100*Panel_Inputs!N7/C7,""),"") -> 0.64069122 | J7: =IF(AND(ISNUMBER(Panel_Inputs!L7),ISNUMBER(Panel_Inputs!O7)),IF(Panel_Inputs!O7>0,100*Panel_Inputs!L7/Panel_Inputs!O7,""),"") | K7: =IF(AND(ISNUMBER(Panel_Inputs!O7),ISNUMBER(Panel_Inputs!K7)),IF(Panel_Inputs!K7>0,100*Panel_Inputs!O7/Panel_Inputs!K7,""),"") | L7: =IF(AND(ISNUMBER(Panel_Inputs!R7),ISNUMBER(Panel_Inputs!K7)),IF(Panel_Inputs!K7>0,100*Panel_Inputs!R7/Panel_Inputs!K7,""),"") | M7: =IF(AND(ISNUMBER(Panel_Inputs!S7),ISNUMBER(Panel_Inputs!R7)),IF(Panel_Inputs!R7>0,100*Panel_Inputs!S7/Panel_Inputs!R7,""),"") | N7: =IF(AND(ISNUMBER(Panel_Inputs!E7),ISNUMBER(Panel_Inputs!F7)),IF(Panel_Inputs!F7>0,100*Panel_Inputs!E7/Panel_Inputs!F7,""),"") -> 2.0687222 | O7: =IF(AND(ISNUMBER(Panel_Inputs!G7),ISNUMBER(Panel_Inputs!F7)),IF(Panel_Inputs!F7>0,100*Panel_Inputs!G7/Panel_Inputs!F7,""),"") -> 86.375315 | P7: =IF(ISNUMBER(Panel_Inputs!F7),IF(Panel_Inputs!F7>0,LN(Panel_Inputs!F7),""),"") -> 14.945286 | Q7: =IF(AND(ISNUMBER(Panel_Inputs!F7),ISNUMBER(Panel_Inputs!G7),ISNUMBER(Panel_Inputs!H7)),Panel_Inputs!F7-Panel_Inputs!G7-Panel_Inputs!H7,"") -> 0 | R7: =IF(AND(ISNUMBER(Panel_Inputs!K7),ISNUMBER(Panel_Inputs!L7),ISNUMBER(Panel_Inputs!M7)),Panel_Inputs!K7-Panel_Inputs!L7-Panel_Inputs!M7,"") -> 0 | S7: =IF(AND(ISNUMBER(Panel_Inputs!V7),Panel_Inputs!W7=1),Panel_Inputs!V7,"") | T7: =IF(AND(ISNUMBER(Panel_Inputs!T7),ISNUMBER(Panel_Inputs!U7)),Panel_Inputs!T7-Panel_Inputs!U7,"") -> 3.55
A8: =Panel_Inputs!A8 -> Access | B8: =Panel_Inputs!B8 -> 2017 | C8: =IF(AND(ISNUMBER(Panel_Inputs!F8),ISNUMBER(Panel_Inputs!J8)),IF(AND(Panel_Inputs!F8>0,Panel_Inputs!J8>0),(Panel_Inputs!F8+Panel_Inputs!J8)/2,""),"") -> 3297322.2 | D8: =IF(AND(ISNUMBER(Panel_Inputs!E8),ISNUMBER(C8)),IF(C8>0,100*Panel_Inputs!E8/C8,""),"") -> 1.6146078 | E8: =IF(AND(ISNUMBER(Panel_Inputs!H8),ISNUMBER(Panel_Inputs!F8)),IF(Panel_Inputs!F8>0,100*Panel_Inputs!H8/Panel_Inputs!F8,""),"") -> 13.415243 | F8: =IF(AND(ISNUMBER(Panel_Inputs!I8),ISNUMBER(C8)),IF(C8>0,100*Panel_Inputs!I8/C8,""),"") -> 3.1650131 | G8: =IF(AND(ISNUMBER(Panel_Inputs!L8),ISNUMBER(Panel_Inputs!K8)),IF(Panel_Inputs!K8>0,100*Panel_Inputs!L8/Panel_Inputs!K8,""),"") -> 3.0800099 | H8: =IF(AND(ISNUMBER(Panel_Inputs!P8),ISNUMBER(Panel_Inputs!Q8)),IF(Panel_Inputs!Q8>0,100*Panel_Inputs!P8/Panel_Inputs!Q8,""),"") -> 18.175202 | I8: =IF(AND(ISNUMBER(Panel_Inputs!N8),ISNUMBER(C8)),IF(C8>0,100*Panel_Inputs!N8/C8,""),"") -> 0.88404611 | J8: =IF(AND(ISNUMBER(Panel_Inputs!L8),ISNUMBER(Panel_Inputs!O8)),IF(Panel_Inputs!O8>0,100*Panel_Inputs!L8/Panel_Inputs!O8,""),"") | K8: =IF(AND(ISNUMBER(Panel_Inputs!O8),ISNUMBER(Panel_Inputs!K8)),IF(Panel_Inputs!K8>0,100*Panel_Inputs!O8/Panel_Inputs!K8,""),"") | L8: =IF(AND(ISNUMBER(Panel_Inputs!R8),ISNUMBER(Panel_Inputs!K8)),IF(Panel_Inputs!K8>0,100*Panel_Inputs!R8/Panel_Inputs!K8,""),"") | M8: =IF(AND(ISNUMBER(Panel_Inputs!S8),ISNUMBER(Panel_Inputs!R8)),IF(Panel_Inputs!R8>0,100*Panel_Inputs!S8/Panel_Inputs!R8,""),"") | N8: =IF(AND(ISNUMBER(Panel_Inputs!E8),ISNUMBER(Panel_Inputs!F8)),IF(Panel_Inputs!F8>0,100*Panel_Inputs!E8/Panel_Inputs!F8,""),"") -> 1.5212466 | O8: =IF(AND(ISNUMBER(Panel_Inputs!G8),ISNUMBER(Panel_Inputs!F8)),IF(Panel_Inputs!F8>0,100*Panel_Inputs!G8/Panel_Inputs!F8,""),"") -> 86.584757 | P8: =IF(ISNUMBER(Panel_Inputs!F8),IF(Panel_Inputs!F8>0,LN(Panel_Inputs!F8),""),"") -> 15.068183 | Q8: =IF(AND(ISNUMBER(Panel_Inputs!F8),ISNUMBER(Panel_Inputs!G8),ISNUMBER(Panel_Inputs!H8)),Panel_Inputs!F8-Panel_Inputs!G8-Panel_Inputs!H8,"") -> 0 | R8: =IF(AND(ISNUMBER(Panel_Inputs!K8),ISNUMBER(Panel_Inputs!L8),ISNUMBER(Panel_Inputs!M8)),Panel_Inputs!K8-Panel_Inputs!L8-Panel_Inputs!M8,"") -> -0.0010000002 | S8: =IF(AND(ISNUMBER(Panel_Inputs!V8),Panel_Inputs!W8=1),Panel_Inputs!V8,"") | T8: =IF(AND(ISNUMBER(Panel_Inputs!T8),ISNUMBER(Panel_Inputs!U8)),Panel_Inputs!T8-Panel_Inputs!U8,"") -> 2.18
A9: =Panel_Inputs!A9 -> Access | B9: =Panel_Inputs!B9 -> 2018 | C9: =IF(AND(ISNUMBER(Panel_Inputs!F9),ISNUMBER(Panel_Inputs!J9)),IF(AND(Panel_Inputs!F9>0,Panel_Inputs!J9>0),(Panel_Inputs!F9+Panel_Inputs!J9)/2,""),"") | D9: =IF(AND(ISNUMBER(Panel_Inputs!E9),ISNUMBER(C9)),IF(C9>0,100*Panel_Inputs!E9/C9,""),"") | E9: =IF(AND(ISNUMBER(Panel_Inputs!H9),ISNUMBER(Panel_Inputs!F9)),IF(Panel_Inputs!F9>0,100*Panel_Inputs!H9/Panel_Inputs!F9,""),"") -> 11.108544 | F9: =IF(AND(ISNUMBER(Panel_Inputs!I9),ISNUMBER(C9)),IF(C9>0,100*Panel_Inputs!I9/C9,""),"") | G9: =IF(AND(ISNUMBER(Panel_Inputs!L9),ISNUMBER(Panel_Inputs!K9)),IF(Panel_Inputs!K9>0,100*Panel_Inputs!L9/Panel_Inputs!K9,""),"") | H9: =IF(AND(ISNUMBER(Panel_Inputs!P9),ISNUMBER(Panel_Inputs!Q9)),IF(Panel_Inputs!Q9>0,100*Panel_Inputs!P9/Panel_Inputs!Q9,""),"") | I9: =IF(AND(ISNUMBER(Panel_Inputs!N9),ISNUMBER(C9)),IF(C9>0,100*Panel_Inputs!N9/C9,""),"") | J9: =IF(AND(ISNUMBER(Panel_Inputs!L9),ISNUMBER(Panel_Inputs!O9)),IF(Panel_Inputs!O9>0,100*Panel_Inputs!L9/Panel_Inputs!O9,""),"") | K9: =IF(AND(ISNUMBER(Panel_Inputs!O9),ISNUMBER(Panel_Inputs!K9)),IF(Panel_Inputs!K9>0,100*Panel_Inputs!O9/Panel_Inputs!K9,""),"") | L9: =IF(AND(ISNUMBER(Panel_Inputs!R9),ISNUMBER(Panel_Inputs!K9)),IF(Panel_Inputs!K9>0,100*Panel_Inputs!R9/Panel_Inputs!K9,""),"") | M9: =IF(AND(ISNUMBER(Panel_Inputs!S9),ISNUMBER(Panel_Inputs!R9)),IF(Panel_Inputs!R9>0,100*Panel_Inputs!S9/Panel_Inputs!R9,""),"") | N9: =IF(AND(ISNUMBER(Panel_Inputs!E9),ISNUMBER(Panel_Inputs!F9)),IF(Panel_Inputs!F9>0,100*Panel_Inputs!E9/Panel_Inputs!F9,""),"") -> 1.8546918 | O9: =IF(AND(ISNUMBER(Panel_Inputs!G9),ISNUMBER(Panel_Inputs!F9)),IF(Panel_Inputs!F9>0,100*Panel_Inputs!G9/Panel_Inputs!F9,""),"") -> 88.891456 | P9: =IF(ISNUMBER(Panel_Inputs!F9),IF(Panel_Inputs!F9>0,LN(Panel_Inputs!F9),""),"") -> 15.193802 | Q9: =IF(AND(ISNUMBER(Panel_Inputs!F9),ISNUMBER(Panel_Inputs!G9),ISNUMBER(Panel_Inputs!H9)),Panel_Inputs!F9-Panel_Inputs!G9-Panel_Inputs!H9,"") -> 0 | R9: =IF(AND(ISNUMBER(Panel_Inputs!K9),ISNUMBER(Panel_Inputs!L9),ISNUMBER(Panel_Inputs!M9)),Panel_Inputs!K9-Panel_Inputs!L9-Panel_Inputs!M9,"") | S9: =IF(AND(ISNUMBER(Panel_Inputs!V9),Panel_Inputs!W9=1),Panel_Inputs!V9,"") | T9: =IF(AND(ISNUMBER(Panel_Inputs!T9),ISNUMBER(Panel_Inputs!U9)),Panel_Inputs!T9-Panel_Inputs!U9,"")
A10: =Panel_Inputs!A10 -> Access | B10: =Panel_Inputs!B10 -> 2019 | C10: =IF(AND(ISNUMBER(Panel_Inputs!F10),ISNUMBER(Panel_Inputs!J10)),IF(AND(Panel_Inputs!F10>0,Panel_Inputs!J10>0),(Panel_Inputs!F10+Panel_Inputs!J10)/2,""),"") -> 5139577.9 | D10: =IF(AND(ISNUMBER(Panel_Inputs!E10),ISNUMBER(C10)),IF(C10>0,100*Panel_Inputs!E10/C10,""),"") -> 1.4314221 | E10: =IF(AND(ISNUMBER(Panel_Inputs!H10),ISNUMBER(Panel_Inputs!F10)),IF(Panel_Inputs!F10>0,100*Panel_Inputs!H10/Panel_Inputs!F10,""),"") -> 8.6030352 | F10: =IF(AND(ISNUMBER(Panel_Inputs!I10),ISNUMBER(C10)),IF(C10>0,100*Panel_Inputs!I10/C10,""),"") -> 21.296948 | G10: =IF(AND(ISNUMBER(Panel_Inputs!L10),ISNUMBER(Panel_Inputs!K10)),IF(Panel_Inputs!K10>0,100*Panel_Inputs!L10/Panel_Inputs!K10,""),"") -> 6.797786 | H10: =IF(AND(ISNUMBER(Panel_Inputs!P10),ISNUMBER(Panel_Inputs!Q10)),IF(Panel_Inputs!Q10>0,100*Panel_Inputs!P10/Panel_Inputs!Q10,""),"") | I10: =IF(AND(ISNUMBER(Panel_Inputs!N10),ISNUMBER(C10)),IF(C10>0,100*Panel_Inputs!N10/C10,""),"") -> 0.40967331 | J10: =IF(AND(ISNUMBER(Panel_Inputs!L10),ISNUMBER(Panel_Inputs!O10)),IF(Panel_Inputs!O10>0,100*Panel_Inputs!L10/Panel_Inputs!O10,""),"") | K10: =IF(AND(ISNUMBER(Panel_Inputs!O10),ISNUMBER(Panel_Inputs!K10)),IF(Panel_Inputs!K10>0,100*Panel_Inputs!O10/Panel_Inputs!K10,""),"") | L10: =IF(AND(ISNUMBER(Panel_Inputs!R10),ISNUMBER(Panel_Inputs!K10)),IF(Panel_Inputs!K10>0,100*Panel_Inputs!R10/Panel_Inputs!K10,""),"") | M10: =IF(AND(ISNUMBER(Panel_Inputs!S10),ISNUMBER(Panel_Inputs!R10)),IF(Panel_Inputs!R10>0,100*Panel_Inputs!S10/Panel_Inputs!R10,""),"") | N10: =IF(AND(ISNUMBER(Panel_Inputs!E10),ISNUMBER(Panel_Inputs!F10)),IF(Panel_Inputs!F10>0,100*Panel_Inputs!E10/Panel_Inputs!F10,""),"") -> 1.1657197 | O10: =IF(AND(ISNUMBER(Panel_Inputs!G10),ISNUMBER(Panel_Inputs!F10)),IF(Panel_Inputs!F10>0,100*Panel_Inputs!G10/Panel_Inputs!F10,""),"") -> 91.396965 | P10: =IF(ISNUMBER(Panel_Inputs!F10),IF(Panel_Inputs!F10>0,LN(Panel_Inputs!F10),""),"") -> 15.657811 | Q10: =IF(AND(ISNUMBER(Panel_Inputs!F10),ISNUMBER(Panel_Inputs!G10),ISNUMBER(Panel_Inputs!H10)),Panel_Inputs!F10-Panel_Inputs!G10-Panel_Inputs!H10,"") -> 0 | R10: =IF(AND(ISNUMBER(Panel_Inputs!K10),ISNUMBER(Panel_Inputs!L10),ISNUMBER(Panel_Inputs!M10)),Panel_Inputs!K10-Panel_Inputs!L10-Panel_Inputs!M10,"") -> -0.0010000002 | S10: =IF(AND(ISNUMBER(Panel_Inputs!V10),Panel_Inputs!W10=1),Panel_Inputs!V10,"") | T10: =IF(AND(ISNUMBER(Panel_Inputs!T10),ISNUMBER(Panel_Inputs!U10)),Panel_Inputs!T10-Panel_Inputs!U10,"")
A11: =Panel_Inputs!A11 -> Access | B11: =Panel_Inputs!B11 -> 2020 | C11: =IF(AND(ISNUMBER(Panel_Inputs!F11),ISNUMBER(Panel_Inputs!J11)),IF(AND(Panel_Inputs!F11>0,Panel_Inputs!J11>0),(Panel_Inputs!F11+Panel_Inputs!J11)/2,""),"") -> 6966284 | D11: =IF(AND(ISNUMBER(Panel_Inputs!E11),ISNUMBER(C11)),IF(C11>0,100*Panel_Inputs!E11/C11,""),"") -> 1.148953 | E11: =IF(AND(ISNUMBER(Panel_Inputs!H11),ISNUMBER(Panel_Inputs!F11)),IF(Panel_Inputs!F11>0,100*Panel_Inputs!H11/Panel_Inputs!F11,""),"") -> 8.5757036 | F11: =IF(AND(ISNUMBER(Panel_Inputs!I11),ISNUMBER(C11)),IF(C11>0,100*Panel_Inputs!I11/C11,""),"") -> -0.93891214 | G11: =IF(AND(ISNUMBER(Panel_Inputs!L11),ISNUMBER(Panel_Inputs!K11)),IF(Panel_Inputs!K11>0,100*Panel_Inputs!L11/Panel_Inputs!K11,""),"") -> 4.051935 | H11: =IF(AND(ISNUMBER(Panel_Inputs!P11),ISNUMBER(Panel_Inputs!Q11)),IF(Panel_Inputs!Q11>0,100*Panel_Inputs!P11/Panel_Inputs!Q11,""),"") -> 15.87392 | I11: =IF(AND(ISNUMBER(Panel_Inputs!N11),ISNUMBER(C11)),IF(C11>0,100*Panel_Inputs!N11/C11,""),"") -> 0.56917835 | J11: =IF(AND(ISNUMBER(Panel_Inputs!L11),ISNUMBER(Panel_Inputs!O11)),IF(Panel_Inputs!O11>0,100*Panel_Inputs!L11/Panel_Inputs!O11,""),"") | K11: =IF(AND(ISNUMBER(Panel_Inputs!O11),ISNUMBER(Panel_Inputs!K11)),IF(Panel_Inputs!K11>0,100*Panel_Inputs!O11/Panel_Inputs!K11,""),"") | L11: =IF(AND(ISNUMBER(Panel_Inputs!R11),ISNUMBER(Panel_Inputs!K11)),IF(Panel_Inputs!K11>0,100*Panel_Inputs!R11/Panel_Inputs!K11,""),"") | M11: =IF(AND(ISNUMBER(Panel_Inputs!S11),ISNUMBER(Panel_Inputs!R11)),IF(Panel_Inputs!R11>0,100*Panel_Inputs!S11/Panel_Inputs!R11,""),"") | N11: =IF(AND(ISNUMBER(Panel_Inputs!E11),ISNUMBER(Panel_Inputs!F11)),IF(Panel_Inputs!F11>0,100*Panel_Inputs!E11/Panel_Inputs!F11,""),"") -> 1.0496989 | O11: =IF(AND(ISNUMBER(Panel_Inputs!G11),ISNUMBER(Panel_Inputs!F11)),IF(Panel_Inputs!F11>0,100*Panel_Inputs!G11/Panel_Inputs!F11,""),"") -> 91.424296 | P11: =IF(ISNUMBER(Panel_Inputs!F11),IF(Panel_Inputs!F11>0,LN(Panel_Inputs!F11),""),"") -> 15.84694 | Q11: =IF(AND(ISNUMBER(Panel_Inputs!F11),ISNUMBER(Panel_Inputs!G11),ISNUMBER(Panel_Inputs!H11)),Panel_Inputs!F11-Panel_Inputs!G11-Panel_Inputs!H11,"") -> 0 | R11: =IF(AND(ISNUMBER(Panel_Inputs!K11),ISNUMBER(Panel_Inputs!L11),ISNUMBER(Panel_Inputs!M11)),Panel_Inputs!K11-Panel_Inputs!L11-Panel_Inputs!M11,"") -> 0 | S11: =IF(AND(ISNUMBER(Panel_Inputs!V11),Panel_Inputs!W11=1),Panel_Inputs!V11,"") | T11: =IF(AND(ISNUMBER(Panel_Inputs!T11),ISNUMBER(Panel_Inputs!U11)),Panel_Inputs!T11-Panel_Inputs!U11,"") -> -0.13
A12: =Panel_Inputs!A12 -> Access | B12: =Panel_Inputs!B12 -> 2021 | C12: =IF(AND(ISNUMBER(Panel_Inputs!F12),ISNUMBER(Panel_Inputs!J12)),IF(AND(Panel_Inputs!F12>0,Panel_Inputs!J12>0),(Panel_Inputs!F12+Panel_Inputs!J12)/2,""),"") -> 8642870.1 | D12: =IF(AND(ISNUMBER(Panel_Inputs!E12),ISNUMBER(C12)),IF(C12>0,100*Panel_Inputs!E12/C12,""),"") -> 1.2880731 | E12: =IF(AND(ISNUMBER(Panel_Inputs!H12),ISNUMBER(Panel_Inputs!F12)),IF(Panel_Inputs!F12>0,100*Panel_Inputs!H12/Panel_Inputs!F12,""),"") -> 9.0205125 | F12: =IF(AND(ISNUMBER(Panel_Inputs!I12),ISNUMBER(C12)),IF(C12>0,100*Panel_Inputs!I12/C12,""),"") -> 5.7947742 | G12: =IF(AND(ISNUMBER(Panel_Inputs!L12),ISNUMBER(Panel_Inputs!K12)),IF(Panel_Inputs!K12>0,100*Panel_Inputs!L12/Panel_Inputs!K12,""),"") -> 2.6213171 | H12: =IF(AND(ISNUMBER(Panel_Inputs!P12),ISNUMBER(Panel_Inputs!Q12)),IF(Panel_Inputs!Q12>0,100*Panel_Inputs!P12/Panel_Inputs!Q12,""),"") -> 20.930667 | I12: =IF(AND(ISNUMBER(Panel_Inputs!N12),ISNUMBER(C12)),IF(C12>0,100*Panel_Inputs!N12/C12,""),"") -> 0.62248922 | J12: =IF(AND(ISNUMBER(Panel_Inputs!L12),ISNUMBER(Panel_Inputs!O12)),IF(Panel_Inputs!O12>0,100*Panel_Inputs!L12/Panel_Inputs!O12,""),"") | K12: =IF(AND(ISNUMBER(Panel_Inputs!O12),ISNUMBER(Panel_Inputs!K12)),IF(Panel_Inputs!K12>0,100*Panel_Inputs!O12/Panel_Inputs!K12,""),"") | L12: =IF(AND(ISNUMBER(Panel_Inputs!R12),ISNUMBER(Panel_Inputs!K12)),IF(Panel_Inputs!K12>0,100*Panel_Inputs!R12/Panel_Inputs!K12,""),"") | M12: =IF(AND(ISNUMBER(Panel_Inputs!S12),ISNUMBER(Panel_Inputs!R12)),IF(Panel_Inputs!R12>0,100*Panel_Inputs!S12/Panel_Inputs!R12,""),"") | N12: =IF(AND(ISNUMBER(Panel_Inputs!E12),ISNUMBER(Panel_Inputs!F12)),IF(Panel_Inputs!F12>0,100*Panel_Inputs!E12/Panel_Inputs!F12,""),"") -> 1.1523574 | O12: =IF(AND(ISNUMBER(Panel_Inputs!G12),ISNUMBER(Panel_Inputs!F12)),IF(Panel_Inputs!F12>0,100*Panel_Inputs!G12/Panel_Inputs!F12,""),"") -> 90.979487 | P12: =IF(ISNUMBER(Panel_Inputs!F12),IF(Panel_Inputs!F12>0,LN(Panel_Inputs!F12),""),"") -> 16.083583 | Q12: =IF(AND(ISNUMBER(Panel_Inputs!F12),ISNUMBER(Panel_Inputs!G12),ISNUMBER(Panel_Inputs!H12)),Panel_Inputs!F12-Panel_Inputs!G12-Panel_Inputs!H12,"") -> 0 | R12: =IF(AND(ISNUMBER(Panel_Inputs!K12),ISNUMBER(Panel_Inputs!L12),ISNUMBER(Panel_Inputs!M12)),Panel_Inputs!K12-Panel_Inputs!L12-Panel_Inputs!M12,"") -> -0.0010000002 | S12: =IF(AND(ISNUMBER(Panel_Inputs!V12),Panel_Inputs!W12=1),Panel_Inputs!V12,"") | T12: =IF(AND(ISNUMBER(Panel_Inputs!T12),ISNUMBER(Panel_Inputs!U12)),Panel_Inputs!T12-Panel_Inputs!U12,"")
A13: =Panel_Inputs!A13 -> Access | B13: =Panel_Inputs!B13 -> 2022 | C13: =IF(AND(ISNUMBER(Panel_Inputs!F13),ISNUMBER(Panel_Inputs!J13)),IF(AND(Panel_Inputs!F13>0,Panel_Inputs!J13>0),(Panel_Inputs!F13+Panel_Inputs!J13)/2,""),"") -> 11098020 | D13: =IF(AND(ISNUMBER(Panel_Inputs!E13),ISNUMBER(C13)),IF(C13>0,100*Panel_Inputs!E13/C13,""),"") -> 1.5017092 | E13: =IF(AND(ISNUMBER(Panel_Inputs!H13),ISNUMBER(Panel_Inputs!F13)),IF(Panel_Inputs!F13>0,100*Panel_Inputs!H13/Panel_Inputs!F13,""),"") -> 8.5252743 | F13: =IF(AND(ISNUMBER(Panel_Inputs!I13),ISNUMBER(C13)),IF(C13>0,100*Panel_Inputs!I13/C13,""),"") -> 6.2941675 | G13: =IF(AND(ISNUMBER(Panel_Inputs!L13),ISNUMBER(Panel_Inputs!K13)),IF(Panel_Inputs!K13>0,100*Panel_Inputs!L13/Panel_Inputs!K13,""),"") -> 1.5679567 | H13: =IF(AND(ISNUMBER(Panel_Inputs!P13),ISNUMBER(Panel_Inputs!Q13)),IF(Panel_Inputs!Q13>0,100*Panel_Inputs!P13/Panel_Inputs!Q13,""),"") -> 17.845932 | I13: =IF(AND(ISNUMBER(Panel_Inputs!N13),ISNUMBER(C13)),IF(C13>0,100*Panel_Inputs!N13/C13,""),"") -> 1.0693889 | J13: =IF(AND(ISNUMBER(Panel_Inputs!L13),ISNUMBER(Panel_Inputs!O13)),IF(Panel_Inputs!O13>0,100*Panel_Inputs!L13/Panel_Inputs!O13,""),"") | K13: =IF(AND(ISNUMBER(Panel_Inputs!O13),ISNUMBER(Panel_Inputs!K13)),IF(Panel_Inputs!K13>0,100*Panel_Inputs!O13/Panel_Inputs!K13,""),"") | L13: =IF(AND(ISNUMBER(Panel_Inputs!R13),ISNUMBER(Panel_Inputs!K13)),IF(Panel_Inputs!K13>0,100*Panel_Inputs!R13/Panel_Inputs!K13,""),"") | M13: =IF(AND(ISNUMBER(Panel_Inputs!S13),ISNUMBER(Panel_Inputs!R13)),IF(Panel_Inputs!R13>0,100*Panel_Inputs!S13/Panel_Inputs!R13,""),"") | N13: =IF(AND(ISNUMBER(Panel_Inputs!E13),ISNUMBER(Panel_Inputs!F13)),IF(Panel_Inputs!F13>0,100*Panel_Inputs!E13/Panel_Inputs!F13,""),"") -> 1.3295275 | O13: =IF(AND(ISNUMBER(Panel_Inputs!G13),ISNUMBER(Panel_Inputs!F13)),IF(Panel_Inputs!F13>0,100*Panel_Inputs!G13/Panel_Inputs!F13,""),"") -> 91.474726 | P13: =IF(ISNUMBER(Panel_Inputs!F13),IF(Panel_Inputs!F13>0,LN(Panel_Inputs!F13),""),"") -> 16.344058 | Q13: =IF(AND(ISNUMBER(Panel_Inputs!F13),ISNUMBER(Panel_Inputs!G13),ISNUMBER(Panel_Inputs!H13)),Panel_Inputs!F13-Panel_Inputs!G13-Panel_Inputs!H13,"") -> 0 | R13: =IF(AND(ISNUMBER(Panel_Inputs!K13),ISNUMBER(Panel_Inputs!L13),ISNUMBER(Panel_Inputs!M13)),Panel_Inputs!K13-Panel_Inputs!L13-Panel_Inputs!M13,"") -> 0 | S13: =IF(AND(ISNUMBER(Panel_Inputs!V13),Panel_Inputs!W13=1),Panel_Inputs!V13,"") | T13: =IF(AND(ISNUMBER(Panel_Inputs!T13),ISNUMBER(Panel_Inputs!U13)),Panel_Inputs!T13-Panel_Inputs!U13,"")
A14: =Panel_Inputs!A14 -> Ecobank Nigeria | B14: =Panel_Inputs!B14 -> 2013 | C14: =IF(AND(ISNUMBER(Panel_Inputs!F14),ISNUMBER(Panel_Inputs!J14)),IF(AND(Panel_Inputs!F14>0,Panel_Inputs!J14>0),(Panel_Inputs!F14+Panel_Inputs!J14)/2,""),"") -> 1393063 | D14: =IF(AND(ISNUMBER(Panel_Inputs!E14),ISNUMBER(C14)),IF(C14>0,100*Panel_Inputs!E14/C14,""),"") -> 0.83686093 | E14: =IF(AND(ISNUMBER(Panel_Inputs!H14),ISNUMBER(Panel_Inputs!F14)),IF(Panel_Inputs!F14>0,100*Panel_Inputs!H14/Panel_Inputs!F14,""),"") -> 10.721989 | F14: =IF(AND(ISNUMBER(Panel_Inputs!I14),ISNUMBER(C14)),IF(C14>0,100*Panel_Inputs!I14/C14,""),"") -> 0.33063831 | G14: =IF(AND(ISNUMBER(Panel_Inputs!L14),ISNUMBER(Panel_Inputs!K14)),IF(Panel_Inputs!K14>0,100*Panel_Inputs!L14/Panel_Inputs!K14,""),"") -> 5.2703828 | H14: =IF(AND(ISNUMBER(Panel_Inputs!P14),ISNUMBER(Panel_Inputs!Q14)),IF(Panel_Inputs!Q14>0,100*Panel_Inputs!P14/Panel_Inputs!Q14,""),"") -> 17.385859 | I14: =IF(AND(ISNUMBER(Panel_Inputs!N14),ISNUMBER(C14)),IF(C14>0,100*Panel_Inputs!N14/C14,""),"") -> 2.3405977 | J14: =IF(AND(ISNUMBER(Panel_Inputs!L14),ISNUMBER(Panel_Inputs!O14)),IF(Panel_Inputs!O14>0,100*Panel_Inputs!L14/Panel_Inputs!O14,""),"") | K14: =IF(AND(ISNUMBER(Panel_Inputs!O14),ISNUMBER(Panel_Inputs!K14)),IF(Panel_Inputs!K14>0,100*Panel_Inputs!O14/Panel_Inputs!K14,""),"") | L14: =IF(AND(ISNUMBER(Panel_Inputs!R14),ISNUMBER(Panel_Inputs!K14)),IF(Panel_Inputs!K14>0,100*Panel_Inputs!R14/Panel_Inputs!K14,""),"") | M14: =IF(AND(ISNUMBER(Panel_Inputs!S14),ISNUMBER(Panel_Inputs!R14)),IF(Panel_Inputs!R14>0,100*Panel_Inputs!S14/Panel_Inputs!R14,""),"") | N14: =IF(AND(ISNUMBER(Panel_Inputs!E14),ISNUMBER(Panel_Inputs!F14)),IF(Panel_Inputs!F14>0,100*Panel_Inputs!E14/Panel_Inputs!F14,""),"") -> 0.79804985 | O14: =IF(AND(ISNUMBER(Panel_Inputs!G14),ISNUMBER(Panel_Inputs!F14)),IF(Panel_Inputs!F14>0,100*Panel_Inputs!G14/Panel_Inputs!F14,""),"") -> 89.278011 | P14: =IF(ISNUMBER(Panel_Inputs!F14),IF(Panel_Inputs!F14>0,LN(Panel_Inputs!F14),""),"") -> 14.194502 | Q14: =IF(AND(ISNUMBER(Panel_Inputs!F14),ISNUMBER(Panel_Inputs!G14),ISNUMBER(Panel_Inputs!H14)),Panel_Inputs!F14-Panel_Inputs!G14-Panel_Inputs!H14,"") -> 0 | R14: =IF(AND(ISNUMBER(Panel_Inputs!K14),ISNUMBER(Panel_Inputs!L14),ISNUMBER(Panel_Inputs!M14)),Panel_Inputs!K14-Panel_Inputs!L14-Panel_Inputs!M14,"") -> 0 | S14: =IF(AND(ISNUMBER(Panel_Inputs!V14),Panel_Inputs!W14=1),Panel_Inputs!V14,"") | T14: =IF(AND(ISNUMBER(Panel_Inputs!T14),ISNUMBER(Panel_Inputs!U14)),Panel_Inputs!T14-Panel_Inputs!U14,"")
A15: =Panel_Inputs!A15 -> Ecobank Nigeria | B15: =Panel_Inputs!B15 -> 2014 | C15: =IF(AND(ISNUMBER(Panel_Inputs!F15),ISNUMBER(Panel_Inputs!J15)),IF(AND(Panel_Inputs!F15>0,Panel_Inputs!J15>0),(Panel_Inputs!F15+Panel_Inputs!J15)/2,""),"") -> 1616866.5 | D15: =IF(AND(ISNUMBER(Panel_Inputs!E15),ISNUMBER(C15)),IF(C15>0,100*Panel_Inputs!E15/C15,""),"") -> 1.8389273 | E15: =IF(AND(ISNUMBER(Panel_Inputs!H15),ISNUMBER(Panel_Inputs!F15)),IF(Panel_Inputs!F15>0,100*Panel_Inputs!H15/Panel_Inputs!F15,""),"") -> 11.190227 | F15: =IF(AND(ISNUMBER(Panel_Inputs!I15),ISNUMBER(C15)),IF(C15>0,100*Panel_Inputs!I15/C15,""),"") -> -6.8466382 | G15: =IF(AND(ISNUMBER(Panel_Inputs!L15),ISNUMBER(Panel_Inputs!K15)),IF(Panel_Inputs!K15>0,100*Panel_Inputs!L15/Panel_Inputs!K15,""),"") -> 4.1070684 | H15: =IF(AND(ISNUMBER(Panel_Inputs!P15),ISNUMBER(Panel_Inputs!Q15)),IF(Panel_Inputs!Q15>0,100*Panel_Inputs!P15/Panel_Inputs!Q15,""),"") -> 16.033592 | I15: =IF(AND(ISNUMBER(Panel_Inputs!N15),ISNUMBER(C15)),IF(C15>0,100*Panel_Inputs!N15/C15,""),"") -> 2.0406137 | J15: =IF(AND(ISNUMBER(Panel_Inputs!L15),ISNUMBER(Panel_Inputs!O15)),IF(Panel_Inputs!O15>0,100*Panel_Inputs!L15/Panel_Inputs!O15,""),"") | K15: =IF(AND(ISNUMBER(Panel_Inputs!O15),ISNUMBER(Panel_Inputs!K15)),IF(Panel_Inputs!K15>0,100*Panel_Inputs!O15/Panel_Inputs!K15,""),"") | L15: =IF(AND(ISNUMBER(Panel_Inputs!R15),ISNUMBER(Panel_Inputs!K15)),IF(Panel_Inputs!K15>0,100*Panel_Inputs!R15/Panel_Inputs!K15,""),"") | M15: =IF(AND(ISNUMBER(Panel_Inputs!S15),ISNUMBER(Panel_Inputs!R15)),IF(Panel_Inputs!R15>0,100*Panel_Inputs!S15/Panel_Inputs!R15,""),"") | N15: =IF(AND(ISNUMBER(Panel_Inputs!E15),ISNUMBER(Panel_Inputs!F15)),IF(Panel_Inputs!F15>0,100*Panel_Inputs!E15/Panel_Inputs!F15,""),"") -> 1.6770619 | O15: =IF(AND(ISNUMBER(Panel_Inputs!G15),ISNUMBER(Panel_Inputs!F15)),IF(Panel_Inputs!F15>0,100*Panel_Inputs!G15/Panel_Inputs!F15,""),"") -> 88.809773 | P15: =IF(ISNUMBER(Panel_Inputs!F15),IF(Panel_Inputs!F15>0,LN(Panel_Inputs!F15),""),"") -> 14.38814 | Q15: =IF(AND(ISNUMBER(Panel_Inputs!F15),ISNUMBER(Panel_Inputs!G15),ISNUMBER(Panel_Inputs!H15)),Panel_Inputs!F15-Panel_Inputs!G15-Panel_Inputs!H15,"") -> 0 | R15: =IF(AND(ISNUMBER(Panel_Inputs!K15),ISNUMBER(Panel_Inputs!L15),ISNUMBER(Panel_Inputs!M15)),Panel_Inputs!K15-Panel_Inputs!L15-Panel_Inputs!M15,"") -> 0 | S15: =IF(AND(ISNUMBER(Panel_Inputs!V15),Panel_Inputs!W15=1),Panel_Inputs!V15,"") | T15: =IF(AND(ISNUMBER(Panel_Inputs!T15),ISNUMBER(Panel_Inputs!U15)),Panel_Inputs!T15-Panel_Inputs!U15,"")
... A121: =Panel_Inputs!A121 -> Zenith | B121: =Panel_Inputs!B121 -> 2022 | C121: =IF(AND(ISNUMBER(Panel_Inputs!F121),ISNUMBER(Panel_Inputs!J121)),IF(AND(Panel_Inputs!F121>0,Panel_Inputs!J121>0),(Panel_Inputs!F121+Panel_Inputs!J121)/2,""),"") -> 9221485 | D121: =IF(AND(ISNUMBER(Panel_Inputs!E121),ISNUMBER(C121)),IF(C121>0,100*Panel_Inputs!E121/C121,""),"") -> 2.5439829 | E121: =IF(AND(ISNUMBER(Panel_Inputs!H121),ISNUMBER(Panel_Inputs!F121)),IF(Panel_Inputs!F121>0,100*Panel_Inputs!H121/Panel_Inputs!F121,""),"") -> 11.306247 | F121: =IF(AND(ISNUMBER(Panel_Inputs!I121),ISNUMBER(C121)),IF(C121>0,100*Panel_Inputs!I121/C121,""),"") -> 13.878003 | G121: =IF(AND(ISNUMBER(Panel_Inputs!L121),ISNUMBER(Panel_Inputs!K121)),IF(Panel_Inputs!K121>0,100*Panel_Inputs!L121/Panel_Inputs!K121,""),"") -> 2.6864871 | H121: =IF(AND(ISNUMBER(Panel_Inputs!P121),ISNUMBER(Panel_Inputs!Q121)),IF(Panel_Inputs!Q121>0,100*Panel_Inputs!P121/Panel_Inputs!Q121,""),"") -> 18.996445 | I121: =IF(AND(ISNUMBER(Panel_Inputs!N121),ISNUMBER(C121)),IF(C121>0,100*Panel_Inputs!N121/C121,""),"") -> 0.6712151 | J121: =IF(AND(ISNUMBER(Panel_Inputs!L121),ISNUMBER(Panel_Inputs!O121)),IF(Panel_Inputs!O121>0,100*Panel_Inputs!L121/Panel_Inputs!O121,""),"") | K121: =IF(AND(ISNUMBER(Panel_Inputs!O121),ISNUMBER(Panel_Inputs!K121)),IF(Panel_Inputs!K121>0,100*Panel_Inputs!O121/Panel_Inputs!K121,""),"") | L121: =IF(AND(ISNUMBER(Panel_Inputs!R121),ISNUMBER(Panel_Inputs!K121)),IF(Panel_Inputs!K121>0,100*Panel_Inputs!R121/Panel_Inputs!K121,""),"") | M121: =IF(AND(ISNUMBER(Panel_Inputs!S121),ISNUMBER(Panel_Inputs!R121)),IF(Panel_Inputs!R121>0,100*Panel_Inputs!S121/Panel_Inputs!R121,""),"") | N121: =IF(AND(ISNUMBER(Panel_Inputs!E121),ISNUMBER(Panel_Inputs!F121)),IF(Panel_Inputs!F121>0,100*Panel_Inputs!E121/Panel_Inputs!F121,""),"") -> 2.2192805 | O121: =IF(AND(ISNUMBER(Panel_Inputs!G121),ISNUMBER(Panel_Inputs!F121)),IF(Panel_Inputs!F121>0,100*Panel_Inputs!G121/Panel_Inputs!F121,""),"") -> 88.693753 | P121: =IF(ISNUMBER(Panel_Inputs!F121),IF(Panel_Inputs!F121>0,LN(Panel_Inputs!F121),""),"") -> 16.173594 | Q121: =IF(AND(ISNUMBER(Panel_Inputs!F121),ISNUMBER(Panel_Inputs!G121),ISNUMBER(Panel_Inputs!H121)),Panel_Inputs!F121-Panel_Inputs!G121-Panel_Inputs!H121,"") -> 0 | R121: =IF(AND(ISNUMBER(Panel_Inputs!K121),ISNUMBER(Panel_Inputs!L121),ISNUMBER(Panel_Inputs!M121)),Panel_Inputs!K121-Panel_Inputs!L121-Panel_Inputs!M121,"") -> 0 | S121: =IF(AND(ISNUMBER(Panel_Inputs!V121),Panel_Inputs!W121=1),Panel_Inputs!V121,"") | T121: =IF(AND(ISNUMBER(Panel_Inputs!T121),ISNUMBER(Panel_Inputs!U121)),Panel_Inputs!T121-Panel_Inputs!U121,"")

Sheet Formula_Check
A1: Python value (from verified_panel.csv) and difference against the workbook formula.
A3: bank | B3: year | C3: average_assets_py | D3: roa_py | E3: eqta_py | F3: ocf_ratio_py | G3: allr_py | H3: car_computed_py | I3: impairment_assets_py | J3: broad_coverage_py | K3: npl_calc_py | L3: stage3_ratio_py | M3: stage3_coverage_py | N3: roa_closing_py | O3: leverage_py | P3: ln_assets_py | Q3: balance_residual_py | R3: loan_residual_py | S3: liquidity_used_py | T3: average_assets_diff | U3: roa_diff | V3: eqta_diff | W3: ocf_ratio_diff | X3: allr_diff | Y3: car_computed_diff | Z3: impairment_assets_diff | AA3: broad_coverage_diff | AB3: npl_calc_diff | AC3: stage3_ratio_diff | AD3: stage3_coverage_diff | AE3: roa_closing_diff | AF3: leverage_diff | AG3: ln_assets_diff | AH3: balance_residual_diff | AI3: loan_residual_diff | AJ3: liquidity_used_diff
A4: Access | B4: 2013 | E4: 14.387821 | N4: 1.5381689 | O4: 85.612179 | P4: 14.348544 | Q4: 1.4551915e-10 | T4: =IF(AND(ISNUMBER(Calculated_Ratios!C4),ISNUMBER(C4)),Calculated_Ratios!C4-C4,IF(AND(Calculated_Ratios!C4="",ISBLANK(C4)),0,"MISMATCH")) -> 0 | U4: =IF(AND(ISNUMBER(Calculated_Ratios!D4),ISNUMBER(D4)),Calculated_Ratios!D4-D4,IF(AND(Calculated_Ratios!D4="",ISBLANK(D4)),0,"MISMATCH")) -> 0 | V4: =IF(AND(ISNUMBER(Calculated_Ratios!E4),ISNUMBER(E4)),Calculated_Ratios!E4-E4,IF(AND(Calculated_Ratios!E4="",ISBLANK(E4)),0,"MISMATCH")) -> 0 | W4: =IF(AND(ISNUMBER(Calculated_Ratios!F4),ISNUMBER(F4)),Calculated_Ratios!F4-F4,IF(AND(Calculated_Ratios!F4="",ISBLANK(F4)),0,"MISMATCH")) -> 0 | X4: =IF(AND(ISNUMBER(Calculated_Ratios!G4),ISNUMBER(G4)),Calculated_Ratios!G4-G4,IF(AND(Calculated_Ratios!G4="",ISBLANK(G4)),0,"MISMATCH")) -> 0 | Y4: =IF(AND(ISNUMBER(Calculated_Ratios!H4),ISNUMBER(H4)),Calculated_Ratios!H4-H4,IF(AND(Calculated_Ratios!H4="",ISBLANK(H4)),0,"MISMATCH")) -> 0 | Z4: =IF(AND(ISNUMBER(Calculated_Ratios!I4),ISNUMBER(I4)),Calculated_Ratios!I4-I4,IF(AND(Calculated_Ratios!I4="",ISBLANK(I4)),0,"MISMATCH")) -> 0 | AA4: =IF(AND(ISNUMBER(Calculated_Ratios!J4),ISNUMBER(J4)),Calculated_Ratios!J4-J4,IF(AND(Calculated_Ratios!J4="",ISBLANK(J4)),0,"MISMATCH")) -> 0 | ... AJ4: =IF(AND(ISNUMBER(Calculated_Ratios!S4),ISNUMBER(S4)),Calculated_Ratios!S4-S4,IF(AND(Calculated_Ratios!S4="",ISBLANK(S4)),0,"MISMATCH")) -> 0
A5: Access | B5: 2014 | C5: 1843024.9 | D5: 2.1671507 | E5: 13.832589 | I5: 0.57564606 | N5: 2.015238 | O5: 86.167411 | P5: 14.499595 | Q5: 0.0010000001 | T5: =IF(AND(ISNUMBER(Calculated_Ratios!C5),ISNUMBER(C5)),Calculated_Ratios!C5-C5,IF(AND(Calculated_Ratios!C5="",ISBLANK(C5)),0,"MISMATCH")) -> 0 | U5: =IF(AND(ISNUMBER(Calculated_Ratios!D5),ISNUMBER(D5)),Calculated_Ratios!D5-D5,IF(AND(Calculated_Ratios!D5="",ISBLANK(D5)),0,"MISMATCH")) -> 0 | V5: =IF(AND(ISNUMBER(Calculated_Ratios!E5),ISNUMBER(E5)),Calculated_Ratios!E5-E5,IF(AND(Calculated_Ratios!E5="",ISBLANK(E5)),0,"MISMATCH")) -> 0 | W5: =IF(AND(ISNUMBER(Calculated_Ratios!F5),ISNUMBER(F5)),Calculated_Ratios!F5-F5,IF(AND(Calculated_Ratios!F5="",ISBLANK(F5)),0,"MISMATCH")) -> 0 | X5: =IF(AND(ISNUMBER(Calculated_Ratios!G5),ISNUMBER(G5)),Calculated_Ratios!G5-G5,IF(AND(Calculated_Ratios!G5="",ISBLANK(G5)),0,"MISMATCH")) -> 0 | Y5: =IF(AND(ISNUMBER(Calculated_Ratios!H5),ISNUMBER(H5)),Calculated_Ratios!H5-H5,IF(AND(Calculated_Ratios!H5="",ISBLANK(H5)),0,"MISMATCH")) -> 0 | Z5: =IF(AND(ISNUMBER(Calculated_Ratios!I5),ISNUMBER(I5)),Calculated_Ratios!I5-I5,IF(AND(Calculated_Ratios!I5="",ISBLANK(I5)),0,"MISMATCH")) -> 0 | AA5: =IF(AND(ISNUMBER(Calculated_Ratios!J5),ISNUMBER(J5)),Calculated_Ratios!J5-J5,IF(AND(Calculated_Ratios!J5="",ISBLANK(J5)),0,"MISMATCH")) -> 0 | ... AJ5: =IF(AND(ISNUMBER(Calculated_Ratios!S5),ISNUMBER(S5)),Calculated_Ratios!S5-S5,IF(AND(Calculated_Ratios!S5="",ISBLANK(S5)),0,"MISMATCH")) -> 0
A6: Access | B6: 2015 | C6: 2196949.9 | D6: 2.682116 | E6: 14.943502 | F6: -8.2499202 | G6: 2.1183867 | H6: 18.039786 | I6: 0.60482094 | N6: 2.4430395 | O6: 85.056498 | P6: 14.695944 | Q6: 3.4924597e-10 | R6: 0 | T6: =IF(AND(ISNUMBER(Calculated_Ratios!C6),ISNUMBER(C6)),Calculated_Ratios!C6-C6,IF(AND(Calculated_Ratios!C6="",ISBLANK(C6)),0,"MISMATCH")) -> 0 | U6: =IF(AND(ISNUMBER(Calculated_Ratios!D6),ISNUMBER(D6)),Calculated_Ratios!D6-D6,IF(AND(Calculated_Ratios!D6="",ISBLANK(D6)),0,"MISMATCH")) -> 0 | V6: =IF(AND(ISNUMBER(Calculated_Ratios!E6),ISNUMBER(E6)),Calculated_Ratios!E6-E6,IF(AND(Calculated_Ratios!E6="",ISBLANK(E6)),0,"MISMATCH")) -> 0 | W6: =IF(AND(ISNUMBER(Calculated_Ratios!F6),ISNUMBER(F6)),Calculated_Ratios!F6-F6,IF(AND(Calculated_Ratios!F6="",ISBLANK(F6)),0,"MISMATCH")) -> 0 | X6: =IF(AND(ISNUMBER(Calculated_Ratios!G6),ISNUMBER(G6)),Calculated_Ratios!G6-G6,IF(AND(Calculated_Ratios!G6="",ISBLANK(G6)),0,"MISMATCH")) -> 0 | Y6: =IF(AND(ISNUMBER(Calculated_Ratios!H6),ISNUMBER(H6)),Calculated_Ratios!H6-H6,IF(AND(Calculated_Ratios!H6="",ISBLANK(H6)),0,"MISMATCH")) -> 0 | Z6: =IF(AND(ISNUMBER(Calculated_Ratios!I6),ISNUMBER(I6)),Calculated_Ratios!I6-I6,IF(AND(Calculated_Ratios!I6="",ISBLANK(I6)),0,"MISMATCH")) -> 0 | AA6: =IF(AND(ISNUMBER(Calculated_Ratios!J6),ISNUMBER(J6)),Calculated_Ratios!J6-J6,IF(AND(Calculated_Ratios!J6="",ISBLANK(J6)),0,"MISMATCH")) -> 0 | ... AJ6: =IF(AND(ISNUMBER(Calculated_Ratios!S6),ISNUMBER(S6)),Calculated_Ratios!S6-S6,IF(AND(Calculated_Ratios!S6="",ISBLANK(S6)),0,"MISMATCH")) -> 0
A7: Access | B7: 2016 | C7: 2753452.3 | D7: 2.325304 | E7: 13.624685 | F7: -4.5083614 | G7: 1.8632945 | H7: 19.554571 | I7: 0.64069122 | N7: 2.0687222 | O7: 86.375315 | P7: 14.945286 | Q7: 1.1641532e-10 | R7: 0 | T7: =IF(AND(ISNUMBER(Calculated_Ratios!C7),ISNUMBER(C7)),Calculated_Ratios!C7-C7,IF(AND(Calculated_Ratios!C7="",ISBLANK(C7)),0,"MISMATCH")) -> 0 | U7: =IF(AND(ISNUMBER(Calculated_Ratios!D7),ISNUMBER(D7)),Calculated_Ratios!D7-D7,IF(AND(Calculated_Ratios!D7="",ISBLANK(D7)),0,"MISMATCH")) -> 0 | V7: =IF(AND(ISNUMBER(Calculated_Ratios!E7),ISNUMBER(E7)),Calculated_Ratios!E7-E7,IF(AND(Calculated_Ratios!E7="",ISBLANK(E7)),0,"MISMATCH")) -> 0 | W7: =IF(AND(ISNUMBER(Calculated_Ratios!F7),ISNUMBER(F7)),Calculated_Ratios!F7-F7,IF(AND(Calculated_Ratios!F7="",ISBLANK(F7)),0,"MISMATCH")) -> 0 | X7: =IF(AND(ISNUMBER(Calculated_Ratios!G7),ISNUMBER(G7)),Calculated_Ratios!G7-G7,IF(AND(Calculated_Ratios!G7="",ISBLANK(G7)),0,"MISMATCH")) -> 0 | Y7: =IF(AND(ISNUMBER(Calculated_Ratios!H7),ISNUMBER(H7)),Calculated_Ratios!H7-H7,IF(AND(Calculated_Ratios!H7="",ISBLANK(H7)),0,"MISMATCH")) -> 0 | Z7: =IF(AND(ISNUMBER(Calculated_Ratios!I7),ISNUMBER(I7)),Calculated_Ratios!I7-I7,IF(AND(Calculated_Ratios!I7="",ISBLANK(I7)),0,"MISMATCH")) -> 0 | AA7: =IF(AND(ISNUMBER(Calculated_Ratios!J7),ISNUMBER(J7)),Calculated_Ratios!J7-J7,IF(AND(Calculated_Ratios!J7="",ISBLANK(J7)),0,"MISMATCH")) -> 0 | ... AJ7: =IF(AND(ISNUMBER(Calculated_Ratios!S7),ISNUMBER(S7)),Calculated_Ratios!S7-S7,IF(AND(Calculated_Ratios!S7="",ISBLANK(S7)),0,"MISMATCH")) -> 0
A8: Access | B8: 2017 | C8: 3297322.2 | D8: 1.6146078 | E8: 13.415243 | F8: 3.1650131 | G8: 3.0800099 | H8: 18.175202 | I8: 0.88404611 | N8: 1.5212466 | O8: 86.584757 | P8: 15.068183 | Q8: -4.0745363e-10 | R8: -0.0010000002 | T8: =IF(AND(ISNUMBER(Calculated_Ratios!C8),ISNUMBER(C8)),Calculated_Ratios!C8-C8,IF(AND(Calculated_Ratios!C8="",ISBLANK(C8)),0,"MISMATCH")) -> 0 | U8: =IF(AND(ISNUMBER(Calculated_Ratios!D8),ISNUMBER(D8)),Calculated_Ratios!D8-D8,IF(AND(Calculated_Ratios!D8="",ISBLANK(D8)),0,"MISMATCH")) -> 0 | V8: =IF(AND(ISNUMBER(Calculated_Ratios!E8),ISNUMBER(E8)),Calculated_Ratios!E8-E8,IF(AND(Calculated_Ratios!E8="",ISBLANK(E8)),0,"MISMATCH")) -> 0 | W8: =IF(AND(ISNUMBER(Calculated_Ratios!F8),ISNUMBER(F8)),Calculated_Ratios!F8-F8,IF(AND(Calculated_Ratios!F8="",ISBLANK(F8)),0,"MISMATCH")) -> 0 | X8: =IF(AND(ISNUMBER(Calculated_Ratios!G8),ISNUMBER(G8)),Calculated_Ratios!G8-G8,IF(AND(Calculated_Ratios!G8="",ISBLANK(G8)),0,"MISMATCH")) -> 0 | Y8: =IF(AND(ISNUMBER(Calculated_Ratios!H8),ISNUMBER(H8)),Calculated_Ratios!H8-H8,IF(AND(Calculated_Ratios!H8="",ISBLANK(H8)),0,"MISMATCH")) -> 0 | Z8: =IF(AND(ISNUMBER(Calculated_Ratios!I8),ISNUMBER(I8)),Calculated_Ratios!I8-I8,IF(AND(Calculated_Ratios!I8="",ISBLANK(I8)),0,"MISMATCH")) -> 0 | AA8: =IF(AND(ISNUMBER(Calculated_Ratios!J8),ISNUMBER(J8)),Calculated_Ratios!J8-J8,IF(AND(Calculated_Ratios!J8="",ISBLANK(J8)),0,"MISMATCH")) -> 0 | ... AJ8: =IF(AND(ISNUMBER(Calculated_Ratios!S8),ISNUMBER(S8)),Calculated_Ratios!S8-S8,IF(AND(Calculated_Ratios!S8="",ISBLANK(S8)),0,"MISMATCH")) -> 0
